Traceback (most recent call last):
  File "/home/khanh/miniconda3/envs/deepai-book/lib/python3.9/site-packages/jupyter_cache/executors/utils.py", line 51, in single_nb_execution
    executenb(
  File "/home/khanh/miniconda3/envs/deepai-book/lib/python3.9/site-packages/nbclient/client.py", line 1093, in execute
    return NotebookClient(nb=nb, resources=resources, km=km, **kwargs).execute()
  File "/home/khanh/miniconda3/envs/deepai-book/lib/python3.9/site-packages/nbclient/util.py", line 84, in wrapped
    return just_run(coro(*args, **kwargs))
  File "/home/khanh/miniconda3/envs/deepai-book/lib/python3.9/site-packages/nbclient/util.py", line 62, in just_run
    return loop.run_until_complete(coro)
  File "/home/khanh/miniconda3/envs/deepai-book/lib/python3.9/asyncio/base_events.py", line 642, in run_until_complete
    return future.result()
  File "/home/khanh/miniconda3/envs/deepai-book/lib/python3.9/site-packages/nbclient/client.py", line 559, in async_execute
    await self.async_execute_cell(
  File "/home/khanh/miniconda3/envs/deepai-book/lib/python3.9/site-packages/nbclient/client.py", line 854, in async_execute_cell
    self._check_raise_for_error(cell, exec_reply)
  File "/home/khanh/miniconda3/envs/deepai-book/lib/python3.9/site-packages/nbclient/client.py", line 756, in _check_raise_for_error
    raise CellExecutionError.from_cell_and_msg(cell, exec_reply_content)
nbclient.exceptions.CellExecutionError: An error occurred while executing the following cell:
------------------
import pprint
from cvxopt import matrix, solvers
c = matrix([50., 150., 120., 40.])

# moi dong cua matrix la 1 list va list nay phai la 1 vec to cot 
G = matrix([[1., 0., -1., 0., 0., 0.],
            [1., 0., 0., -1., 0., 0.],
            [0., 1., 0., 0., -1., 0.],
            [0., 1., 0., 0., 0., -1.]])

h = matrix([1000., 3000., 0., 0., 0., 0.])

A = matrix([[1., 0.],
            [0., 1.],
            [1., 0.],
            [0., 1.]])

b = matrix([1800., 2000.])

solvers.options['show_progress'] = True
sol = solvers.lp(c, G, h, A, b)

print('Solution"')
print(sol['x'])
------------------

[0;31m---------------------------------------------------------------------------[0m
[0;31mModuleNotFoundError[0m                       Traceback (most recent call last)
[0;32m/tmp/ipykernel_42718/1023612750.py[0m in [0;36m<module>[0;34m[0m
[1;32m      1[0m [0;32mimport[0m [0mpprint[0m[0;34m[0m[0;34m[0m[0m
[0;32m----> 2[0;31m [0;32mfrom[0m [0mcvxopt[0m [0;32mimport[0m [0mmatrix[0m[0;34m,[0m [0msolvers[0m[0;34m[0m[0;34m[0m[0m
[0m[1;32m      3[0m [0mc[0m [0;34m=[0m [0mmatrix[0m[0;34m([0m[0;34m[[0m[0;36m50.[0m[0;34m,[0m [0;36m150.[0m[0;34m,[0m [0;36m120.[0m[0;34m,[0m [0;36m40.[0m[0;34m][0m[0;34m)[0m[0;34m[0m[0;34m[0m[0m
[1;32m      4[0m [0;34m[0m[0m
[1;32m      5[0m [0;31m# moi dong cua matrix la 1 list va list nay phai la 1 vec to cot[0m[0;34m[0m[0;34m[0m[0m

[0;31mModuleNotFoundError[0m: No module named 'cvxopt'
ModuleNotFoundError: No module named 'cvxopt'

