Traceback (most recent call last):
  File "/home/khanh/miniconda3/lib/python3.9/site-packages/jupyter_cache/executors/utils.py", line 51, in single_nb_execution
    executenb(
  File "/home/khanh/miniconda3/lib/python3.9/site-packages/nbclient/client.py", line 1093, in execute
    return NotebookClient(nb=nb, resources=resources, km=km, **kwargs).execute()
  File "/home/khanh/miniconda3/lib/python3.9/site-packages/nbclient/util.py", line 84, in wrapped
    return just_run(coro(*args, **kwargs))
  File "/home/khanh/miniconda3/lib/python3.9/site-packages/nbclient/util.py", line 62, in just_run
    return loop.run_until_complete(coro)
  File "/home/khanh/miniconda3/lib/python3.9/asyncio/base_events.py", line 642, in run_until_complete
    return future.result()
  File "/home/khanh/miniconda3/lib/python3.9/site-packages/nbclient/client.py", line 559, in async_execute
    await self.async_execute_cell(
  File "/home/khanh/miniconda3/lib/python3.9/site-packages/nbclient/client.py", line 854, in async_execute_cell
    self._check_raise_for_error(cell, exec_reply)
  File "/home/khanh/miniconda3/lib/python3.9/site-packages/nbclient/client.py", line 756, in _check_raise_for_error
    raise CellExecutionError.from_cell_and_msg(cell, exec_reply_content)
nbclient.exceptions.CellExecutionError: An error occurred while executing the following cell:
------------------
import numpy as np
import matplotlib.pyplot as plt

fig, ax = plt.subplots(1, 2, figsize = (18, 6))
z = np.linspace(-3, 3, 100)

def sigmoid(z):
  return 1/(1+np.exp(-z))

y0 = -np.log(1-sigmoid(z)) # Tr∆∞·ªùng h·ª£p ground truth = 0
y1 = -np.log(sigmoid(z)) # Tr∆∞·ªùng h·ª£p ground truth = 1

# H√†m m·∫•t m√°t n·∫øu ground truth = 1
ax[0].plot(z, y1)
ax[0].set_xlabel('z')
ax[0].set_ylabel('L(y, yhat)')
ax[0].set_title('y=1')

# H√†m m·∫•t m√°t n·∫øu ground truth = 0
ax[1].plot(z, y0)
ax[1].set_xlabel('z')
ax[1].set_ylabel('L(y, yhat)')
ax[1].set_title('y=0')

plt.show()
------------------

[0;31m---------------------------------------------------------------------------[0m
[0;31mModuleNotFoundError[0m                       Traceback (most recent call last)
[0;32m/tmp/ipykernel_76988/3221669990.py[0m in [0;36m<module>[0;34m[0m
[1;32m      1[0m [0;32mimport[0m [0mnumpy[0m [0;32mas[0m [0mnp[0m[0;34m[0m[0;34m[0m[0m
[0;32m----> 2[0;31m [0;32mimport[0m [0mmatplotlib[0m[0;34m.[0m[0mpyplot[0m [0;32mas[0m [0mplt[0m[0;34m[0m[0;34m[0m[0m
[0m[1;32m      3[0m [0;34m[0m[0m
[1;32m      4[0m [0mfig[0m[0;34m,[0m [0max[0m [0;34m=[0m [0mplt[0m[0;34m.[0m[0msubplots[0m[0;34m([0m[0;36m1[0m[0;34m,[0m [0;36m2[0m[0;34m,[0m [0mfigsize[0m [0;34m=[0m [0;34m([0m[0;36m18[0m[0;34m,[0m [0;36m6[0m[0;34m)[0m[0;34m)[0m[0;34m[0m[0;34m[0m[0m
[1;32m      5[0m [0mz[0m [0;34m=[0m [0mnp[0m[0;34m.[0m[0mlinspace[0m[0;34m([0m[0;34m-[0m[0;36m3[0m[0;34m,[0m [0;36m3[0m[0;34m,[0m [0;36m100[0m[0;34m)[0m[0;34m[0m[0;34m[0m[0m

[0;31mModuleNotFoundError[0m: No module named 'matplotlib'
ModuleNotFoundError: No module named 'matplotlib'

